2020-05-28 13:11:23,697 INFO: Weather report backend startup [in /Users/i505979/Documents/weather/weather-report/backend/app.py:22]
2020-05-28 13:12:02,473 ERROR: Exception on /weather_/3 [GET] [in /Users/i505979/Documents/weather/weather-report/.venv/lib/python3.7/site-packages/flask/app.py:1892]
Traceback (most recent call last):
  File "/Users/i505979/Documents/weather/weather-report/.venv/lib/python3.7/site-packages/flask/app.py", line 1950, in full_dispatch_request
    rv = self.dispatch_request()
  File "/Users/i505979/Documents/weather/weather-report/.venv/lib/python3.7/site-packages/flask/app.py", line 1926, in dispatch_request
    self.raise_routing_exception(req)
  File "/Users/i505979/Documents/weather/weather-report/.venv/lib/python3.7/site-packages/flask/app.py", line 1908, in raise_routing_exception
    raise request.routing_exception
  File "/Users/i505979/Documents/weather/weather-report/.venv/lib/python3.7/site-packages/flask/ctx.py", line 350, in match_request
    result = self.url_adapter.match(return_rule=True)
  File "/Users/i505979/Documents/weather/weather-report/.venv/lib/python3.7/site-packages/werkzeug/routing.py", line 1945, in match
    raise NotFound()
werkzeug.exceptions.NotFound: 404 Not Found: The requested URL was not found on the server. If you entered the URL manually please check your spelling and try again.

During handling of the above exception, another exception occurred:

Traceback (most recent call last):
  File "/Users/i505979/Documents/weather/weather-report/.venv/lib/python3.7/site-packages/flask/app.py", line 2447, in wsgi_app
    response = self.full_dispatch_request()
  File "/Users/i505979/Documents/weather/weather-report/.venv/lib/python3.7/site-packages/flask/app.py", line 1952, in full_dispatch_request
    rv = self.handle_user_exception(e)
  File "/Users/i505979/Documents/weather/weather-report/.venv/lib/python3.7/site-packages/flask/app.py", line 1816, in handle_user_exception
    return self.handle_http_exception(e)
  File "/Users/i505979/Documents/weather/weather-report/.venv/lib/python3.7/site-packages/flask/app.py", line 1744, in handle_http_exception
    return handler(e)
  File "/Users/i505979/Documents/weather/weather-report/backend/app.py", line 41, in not_found_error
    return render_template('404.html'), 404
  File "/Users/i505979/Documents/weather/weather-report/.venv/lib/python3.7/site-packages/flask/templating.py", line 138, in render_template
    ctx.app.jinja_env.get_or_select_template(template_name_or_list),
  File "/Users/i505979/Documents/weather/weather-report/.venv/lib/python3.7/site-packages/jinja2/environment.py", line 930, in get_or_select_template
    return self.get_template(template_name_or_list, parent, globals)
  File "/Users/i505979/Documents/weather/weather-report/.venv/lib/python3.7/site-packages/jinja2/environment.py", line 883, in get_template
    return self._load_template(name, self.make_globals(globals))
  File "/Users/i505979/Documents/weather/weather-report/.venv/lib/python3.7/site-packages/jinja2/environment.py", line 857, in _load_template
    template = self.loader.load(self, name, globals)
  File "/Users/i505979/Documents/weather/weather-report/.venv/lib/python3.7/site-packages/jinja2/loaders.py", line 115, in load
    source, filename, uptodate = self.get_source(environment, name)
  File "/Users/i505979/Documents/weather/weather-report/.venv/lib/python3.7/site-packages/flask/templating.py", line 60, in get_source
    return self._get_source_fast(environment, template)
  File "/Users/i505979/Documents/weather/weather-report/.venv/lib/python3.7/site-packages/flask/templating.py", line 89, in _get_source_fast
    raise TemplateNotFound(template)
jinja2.exceptions.TemplateNotFound: 404.html
2020-05-28 13:19:57,769 INFO: Weather report backend startup [in /Users/i505979/Documents/weather/weather-report/backend/app.py:22]
2020-05-28 13:20:13,203 ERROR: (psycopg2.errors.SyntaxError) syntax error at or near ")"
LINE 3: ...(SELECT max(days) FROM weather) - INTERVAL '3 DAY') AND (SEL...
                                                             ^

[SQL: SELECT weather.days AS weather_days, weather.temperature AS weather_temperature, weather.pressure AS weather_pressure 
FROM weather 
WHERE weather.days BETWEEN (SELECT max(days) FROM weather) - INTERVAL '3 DAY') AND (SELECT max(days) FROM weather)]
(Background on this error at: http://sqlalche.me/e/f405) [in /Users/i505979/Documents/weather/weather-report/backend/app.py:35]
2020-05-28 13:21:02,852 INFO: Weather report backend startup [in /Users/i505979/Documents/weather/weather-report/backend/app.py:22]
2020-05-28 13:23:24,929 INFO: Weather report backend startup [in /Users/i505979/Documents/weather/weather-report/backend/app.py:22]
2020-05-28 13:23:50,139 ERROR: (psycopg2.errors.SyntaxError) syntax error at or near ")"
LINE 3: ...(SELECT max(days) FROM weather) - INTERVAL '3 DAY') AND (SEL...
                                                             ^

[SQL: SELECT weather.days AS weather_days, weather.temperature AS weather_temperature, weather.pressure AS weather_pressure 
FROM weather 
WHERE weather.days BETWEEN (SELECT max(days) FROM weather) - INTERVAL '3 DAY') AND (SELECT max(days) FROM weather)]
(Background on this error at: http://sqlalche.me/e/f405) [in /Users/i505979/Documents/weather/weather-report/backend/app.py:35]
2020-05-28 13:23:52,880 ERROR: (psycopg2.errors.SyntaxError) syntax error at or near ")"
LINE 3: ...(SELECT max(days) FROM weather) - INTERVAL '3 DAY') AND (SEL...
                                                             ^

[SQL: SELECT weather.days AS weather_days, weather.temperature AS weather_temperature, weather.pressure AS weather_pressure 
FROM weather 
WHERE weather.days BETWEEN (SELECT max(days) FROM weather) - INTERVAL '3 DAY') AND (SELECT max(days) FROM weather)]
(Background on this error at: http://sqlalche.me/e/f405) [in /Users/i505979/Documents/weather/weather-report/backend/app.py:35]
2020-05-28 13:24:03,028 INFO: Weather report backend startup [in /Users/i505979/Documents/weather/weather-report/backend/app.py:22]
2020-05-28 13:25:58,480 INFO: Weather report backend startup [in /Users/i505979/Documents/weather/weather-report/backend/app.py:21]
2020-05-28 13:41:14,338 INFO: Weather report backend startup [in /Users/i505979/Documents/weather/weather-report/backend/app.py:21]
2020-05-28 13:42:22,403 INFO: Weather report backend startup [in /Users/i505979/Documents/weather/weather-report/backend/app.py:21]
2020-05-28 13:49:12,623 INFO: Weather report backend startup [in /Users/i505979/Documents/weather/weather-report/backend/app.py:21]
2020-05-28 14:08:45,722 INFO: Weather report backend startup [in /Users/i505979/Documents/weather/weather-report/backend/app.py:21]
2020-05-28 14:08:58,278 ERROR: Exception on /weather/3 [GET] [in /Users/i505979/Documents/weather/weather-report/.venv/lib/python3.7/site-packages/flask/app.py:1892]
Traceback (most recent call last):
  File "/Users/i505979/Documents/weather/weather-report/.venv/lib/python3.7/site-packages/flask/app.py", line 2447, in wsgi_app
    response = self.full_dispatch_request()
  File "/Users/i505979/Documents/weather/weather-report/.venv/lib/python3.7/site-packages/flask/app.py", line 1953, in full_dispatch_request
    return self.finalize_request(rv)
  File "/Users/i505979/Documents/weather/weather-report/.venv/lib/python3.7/site-packages/flask/app.py", line 1968, in finalize_request
    response = self.make_response(rv)
  File "/Users/i505979/Documents/weather/weather-report/.venv/lib/python3.7/site-packages/flask/app.py", line 2112, in make_response
    rv = jsonify(rv)
  File "/Users/i505979/Documents/weather/weather-report/.venv/lib/python3.7/site-packages/flask/json/__init__.py", line 370, in jsonify
    dumps(data, indent=indent, separators=separators) + "\n",
  File "/Users/i505979/Documents/weather/weather-report/.venv/lib/python3.7/site-packages/flask/json/__init__.py", line 211, in dumps
    rv = _json.dumps(obj, **kwargs)
  File "/usr/local/Cellar/python/3.7.4/Frameworks/Python.framework/Versions/3.7/lib/python3.7/json/__init__.py", line 238, in dumps
    **kw).encode(obj)
  File "/usr/local/Cellar/python/3.7.4/Frameworks/Python.framework/Versions/3.7/lib/python3.7/json/encoder.py", line 199, in encode
    chunks = self.iterencode(o, _one_shot=True)
  File "/usr/local/Cellar/python/3.7.4/Frameworks/Python.framework/Versions/3.7/lib/python3.7/json/encoder.py", line 257, in iterencode
    return _iterencode(o, 0)
  File "/Users/i505979/Documents/weather/weather-report/.venv/lib/python3.7/site-packages/flask/json/__init__.py", line 100, in default
    return _json.JSONEncoder.default(self, o)
  File "/usr/local/Cellar/python/3.7.4/Frameworks/Python.framework/Versions/3.7/lib/python3.7/json/encoder.py", line 179, in default
    raise TypeError(f'Object of type {o.__class__.__name__} '
TypeError: Object of type BaseQuery is not JSON serializable
2020-05-28 14:09:23,085 INFO: Weather report backend startup [in /Users/i505979/Documents/weather/weather-report/backend/app.py:21]
2020-05-28 14:20:01,419 INFO: Weather report backend startup [in /Users/i505979/Documents/weather/weather-report/backend/app.py:21]
2020-05-28 14:23:07,530 INFO: Weather report backend startup [in /Users/i505979/Documents/weather/weather-report/backend/app.py:21]
2020-05-28 14:23:51,556 INFO: Weather report backend startup [in /Users/i505979/Documents/weather/weather-report/backend/app.py:21]
2020-05-28 14:24:25,653 INFO: Weather report backend startup [in /Users/i505979/Documents/weather/weather-report/backend/app.py:21]
